2025-06-02 21:11:04,502 INFO    MainThread:18968 [wandb_setup.py:_flush():68] Current SDK version is 0.19.10
2025-06-02 21:11:04,502 INFO    MainThread:18968 [wandb_setup.py:_flush():68] Configure stats pid to 18968
2025-06-02 21:11:04,502 INFO    MainThread:18968 [wandb_setup.py:_flush():68] Loading settings from C:\Users\lapla\.config\wandb\settings
2025-06-02 21:11:04,502 INFO    MainThread:18968 [wandb_setup.py:_flush():68] Loading settings from C:\Users\lapla\Downloads\FlowTransformer-master\wandb\settings
2025-06-02 21:11:04,502 INFO    MainThread:18968 [wandb_setup.py:_flush():68] Loading settings from environment variables
2025-06-02 21:11:04,502 INFO    MainThread:18968 [wandb_init.py:setup_run_log_directory():724] Logging user logs to C:\Users\lapla\Downloads\FlowTransformer-master\wandb\run-20250602_211104-uot7gtq1\logs\debug.log
2025-06-02 21:11:04,503 INFO    MainThread:18968 [wandb_init.py:setup_run_log_directory():725] Logging internal logs to C:\Users\lapla\Downloads\FlowTransformer-master\wandb\run-20250602_211104-uot7gtq1\logs\debug-internal.log
2025-06-02 21:11:04,503 INFO    MainThread:18968 [wandb_init.py:init():852] calling init triggers
2025-06-02 21:11:04,503 INFO    MainThread:18968 [wandb_init.py:init():857] wandb.init called with sweep_config: {}
config: {'_wandb': {}}
2025-06-02 21:11:04,503 INFO    MainThread:18968 [wandb_init.py:init():893] starting backend
2025-06-02 21:11:04,503 INFO    MainThread:18968 [wandb_init.py:init():897] sending inform_init request
2025-06-02 21:11:04,545 INFO    MainThread:18968 [backend.py:_multiprocessing_setup():101] multiprocessing start_methods=spawn, using: spawn
2025-06-02 21:11:04,545 INFO    MainThread:18968 [wandb_init.py:init():907] backend started and connected
2025-06-02 21:11:04,546 INFO    MainThread:18968 [wandb_init.py:init():1002] updated telemetry
2025-06-02 21:11:04,548 INFO    MainThread:18968 [wandb_init.py:init():1026] communicating run to backend with 90.0 second timeout
2025-06-02 21:11:05,673 INFO    MainThread:18968 [wandb_init.py:init():1101] starting run threads in backend
2025-06-02 21:11:08,295 INFO    MainThread:18968 [wandb_run.py:_console_start():2566] atexit reg
2025-06-02 21:11:08,296 INFO    MainThread:18968 [wandb_run.py:_redirect():2414] redirect: wrap_raw
2025-06-02 21:11:08,296 INFO    MainThread:18968 [wandb_run.py:_redirect():2483] Wrapping output streams.
2025-06-02 21:11:08,296 INFO    MainThread:18968 [wandb_run.py:_redirect():2506] Redirects installed.
2025-06-02 21:11:08,323 INFO    MainThread:18968 [wandb_init.py:init():1147] run started, returning control to user process
2025-06-02 21:14:46,912 WARNING MsgRouterThr:18968 [router.py:message_loop():63] [no run ID] message_loop has been closed
Traceback (most recent call last):
  File "C:\Users\lapla\AppData\Local\Packages\PythonSoftwareFoundation.Python.3.11_qbz5n2kfra8p0\LocalCache\local-packages\Python311\site-packages\wandb\sdk\lib\sock_client.py", line 208, in _read_packet_bytes
    data = self._sock.recv(self._bufsize)
           ^^^^^^^^^^^^^^^^^^^^^^^^^^^^^^
ConnectionResetError: [WinError 10054] Se ha forzado la interrupción de una conexión existente por el host remoto

The above exception was the direct cause of the following exception:

Traceback (most recent call last):
  File "C:\Users\lapla\AppData\Local\Packages\PythonSoftwareFoundation.Python.3.11_qbz5n2kfra8p0\LocalCache\local-packages\Python311\site-packages\wandb\sdk\interface\router_sock.py", line 27, in _read_message
    return self._sock_client.read_server_response(timeout=1)
           ^^^^^^^^^^^^^^^^^^^^^^^^^^^^^^^^^^^^^^^^^^^^^^^^^
  File "C:\Users\lapla\AppData\Local\Packages\PythonSoftwareFoundation.Python.3.11_qbz5n2kfra8p0\LocalCache\local-packages\Python311\site-packages\wandb\sdk\lib\sock_client.py", line 235, in read_server_response
    data = self._read_packet_bytes(timeout=timeout)
           ^^^^^^^^^^^^^^^^^^^^^^^^^^^^^^^^^^^^^^^^
  File "C:\Users\lapla\AppData\Local\Packages\PythonSoftwareFoundation.Python.3.11_qbz5n2kfra8p0\LocalCache\local-packages\Python311\site-packages\wandb\sdk\lib\sock_client.py", line 212, in _read_packet_bytes
    raise SockClientClosedError from e
wandb.sdk.lib.sock_client.SockClientClosedError

The above exception was the direct cause of the following exception:

Traceback (most recent call last):
  File "C:\Users\lapla\AppData\Local\Packages\PythonSoftwareFoundation.Python.3.11_qbz5n2kfra8p0\LocalCache\local-packages\Python311\site-packages\wandb\sdk\interface\router.py", line 56, in message_loop
    msg = self._read_message()
          ^^^^^^^^^^^^^^^^^^^^
  File "C:\Users\lapla\AppData\Local\Packages\PythonSoftwareFoundation.Python.3.11_qbz5n2kfra8p0\LocalCache\local-packages\Python311\site-packages\wandb\sdk\interface\router_sock.py", line 29, in _read_message
    raise MessageRouterClosedError from e
wandb.sdk.interface.router.MessageRouterClosedError
2025-06-02 21:14:47,361 INFO    MsgRouterThr:18968 [mailbox.py:close():129] [no run ID] Closing mailbox, abandoning 3 handles.
